Workbook

Sheet Duże autobusy
A1: Model | B1: moc silnika [KM] | C1: miejsca dla pasażerów | D1: udogodnienia dla niepełnosprawnych | E1: koszt zakupu [mln zł] | F1: prestiż
A2: Solaris
A3: Urbino 15 LE electric | B3: 408 | C3: 65 | D3: niska podłoga, przyklęk | E3: 2.2 | F3: =AVERAGE(10,6,5) -> 7
A4: Urbino 18 CNG | B4: 320 | C4: 55 | D4: niska podłoga, miejsce na wózek, przyklęk | E4: 2.4 | F4: 10
A5: Urbino 18 | B5: 310 | C5: 54 | D5: niska podłoga, miejsce na wózek, przyklęk | E5: 1.8 | F5: =AVERAGE(5,4,10) -> 6.3333333
A6: Urbino 12 | B6: 256 | C6: 16 | D6: niska podłoga, miejsce na wózek, przyklęk | E6: 1 | F6: =AVERAGE(8,8,10) -> 8.6666667
A7: Urbino 12 CNG | B7: 320 | C7: 40 | D7: niska podłoga, miejsce na wózek, przyklęk | E7: 1.1 | F7: =AVERAGE(3,1,10) -> 4.6666667
A8: MAN bus
A9: MAN Lion's City 12 E | B9: 326 | C9: 44 | D9: niska podłoga, rampa, miejsce na wózek, przyklęk | E9: 2.6 | F9: =AVERAGE(7,4,8) -> 6.3333333
A10: MAN Lion's Intercity LE 14 | B10: 265 | C10: 63 | D10: niska podłoga, miejsce na wózek, przyklęk | E10: 1.8 | F10: =AVERAGE(9,4,6) -> 6.3333333
A11: MAN Lion's City 12 G | B11: 280 | C11: 37 | D11: niska podłoga, rampa, miejsce na wózek, przyklęk | E11: 2 | F11: =AVERAGE(4,4,1) -> 3
A12: Autosan
A13: SANCITY 12LFH | B13: 344 | C13: 40 | D13: niska podłoga, rampa, miejsce na wózek | E13: 3.25 | F13: =AVERAGE(10,10,4) -> 8
A14: SANCITY 12LF | B14: 277 | C14: 40 | D14: niska podłoga, rampa, miejsce na wózek | E14: 1 | F14: =AVERAGE(5,4,3) -> 4
A15: Mercedes
A16: CapaCity L | B16: 360 | C16: 44 | D16: niska podłoga, rampa, miejsce na wózek, przyklęk | E16: 2 | F16: =AVERAGE(8,9,9) -> 8.6666667
A17: Nesobus
A18: Nesobus 12 | B18: 340 | C18: 37 | D18: niska podłoga, rampa, miejsce na wózek | E18: 2.9 | F18: =AVERAGE(10,9,10) -> 9.6666667
D20: =IF(D3="",0, LEN(D3) - LEN(SUBSTITUTE(D3,",",""))+1) -> 2

Sheet Średnie autobusy
A1: Model | B1: moc silnika [KM] | C1: miejsca dla pasażerów | D1: udogodnienia dla niepełnosprawnych | E1: koszt zakupu [mln zł] | F1: prestiż
A2: Solaris
A3: Urbino 10,5 electric | B3: 340 | C3: 33 | D3: niska podłoga, miejsce na wózek, przyklęk | E3: 2.6 | F3: =AVERAGE(6,4,2) -> 4
A4: Urbino 8,9 LE electric | B4: 218 | C4: 27 | D4: niska podłoga, rampa, miejsce na wózek, przyklęk | E4: 2.4 | F4: =AVERAGE(6,8,10) -> 8
A5: Urbino 8,9 LE | B5: 250 | C5: 33 | D5: niska podłoga, rampa, miejsce na wózek, przyklęk | E5: 1.1 | F5: =AVERAGE(10,5,5) -> 6.6666667
A6: MAN bus
A7: MAN Lion's City 10 E | B7: 326 | C7: 36 | D7: niska podłoga, rampa, miejsce na wózek, przyklęk | E7: 2.6 | F7: =AVERAGE(5,5,5) -> 5
A8: Autosan
A9: SANCITY 9LE | B9: 210 | C9: 16 | D9: niska podłoga, rampa, miejsce na wózek, braille/piktogramy | E9: 0.6 | F9: =AVERAGE(3,6,4) -> 4.3333333
A10: SANCITY 10LFE | B10: 340 | C10: 24 | D10: niska podłoga, rampa, miejsce na wózek, przyklęk | E10: 2.2 | F10: =AVERAGE(5,6,4) -> 5
A11: SANCITY 10LF | B11: 247 | C11: 26 | D11: niska podłoga, rampa, miejsce na wózek | E11: 0.9 | F11: =AVERAGE(5,7,5) -> 5.6666667
A12: Mercedes
A13: Citaro K | B13: 299 | C13: 32 | D13: niska podłoga, rampa, miejsce na wózek, przyklęk, braille/piktogramy | E13: 1.3 | F13: =AVERAGE(9,9,7) -> 8.3333333
A14: Iveco Bus
A15: Crossway 10.8LE | B15: 330 | C15: 29 | D15: niska podłoga, rampa, miejsce na wózek, przyklęk | E15: 1.1 | F15: =AVERAGE(9,7,10) -> 8.6666667
A16: Crossway Pro 10,8 | B16: 360 | C16: 47 | D16: rampa, miejsce na wózek, przyklęk | E16: 0.9 | F16: =AVERAGE(8,3,8) -> 6.3333333

Sheet Duże autobusy SAW
A1: Model | B1: moc silnika [KM] MAX | C1: miejsca dla pasażerów MAX | D1: udogodnienia dla niepełnosprawnych MAX | E1: koszt zakupu [mln zł] MIN | F1: prestiż MAX
A2: Urbino 15 LE electric | B2: 408 | C2: 65 | D2: =IF('Duże autobusy'!$D$3="",0, LEN('Duże autobusy'!$D$3) - LEN(SUBSTITUTE('Duże autobusy'!$D$3,",",""))+1) -> 2 | E2: 2.2 | F2: =AVERAGE(10,6,5) -> 7
A3: Urbino 18 CNG | B3: 320 | C3: 55 | D3: =IF('Duże autobusy'!$D$4="",0, LEN('Duże autobusy'!$D$4) - LEN(SUBSTITUTE('Duże autobusy'!$D$4,",",""))+1) -> 3 | E3: 2.4 | F3: 10
A4: Urbino 18 | B4: 310 | C4: 54 | D4: =IF('Duże autobusy'!$D$5="",0, LEN('Duże autobusy'!$D$5) - LEN(SUBSTITUTE('Duże autobusy'!$D$5,",",""))+1) -> 3 | E4: 1.8 | F4: =AVERAGE(5,4,10) -> 6.3333333
A5: Urbino 12 | B5: 256 | C5: 16 | D5: =IF('Duże autobusy'!$D$6="",0, LEN('Duże autobusy'!$D$6) - LEN(SUBSTITUTE('Duże autobusy'!$D$6,",",""))+1) -> 3 | E5: 1 | F5: =AVERAGE(8,8,10) -> 8.6666667
A6: Urbino 12 CNG | B6: 320 | C6: 40 | D6: =IF('Duże autobusy'!$D$7="",0, LEN('Duże autobusy'!$D$7) - LEN(SUBSTITUTE('Duże autobusy'!$D$7,",",""))+1) -> 3 | E6: 1.1 | F6: =AVERAGE(3,1,10) -> 4.6666667
A7: MAN Lion's City 12 E | B7: 326 | C7: 44 | D7: =IF('Duże autobusy'!$D$9="",0, LEN('Duże autobusy'!$D$9) - LEN(SUBSTITUTE('Duże autobusy'!$D$9,",",""))+1) -> 4 | E7: 2.6 | F7: =AVERAGE(7,4,8) -> 6.3333333
A8: MAN Lion's Intercity LE 14 | B8: 265 | C8: 63 | D8: =IF('Duże autobusy'!$D$10="",0, LEN('Duże autobusy'!$D$10) - LEN(SUBSTITUTE('Duże autobusy'!$D$10,",",""))+1) -> 3 | E8: 1.8 | F8: =AVERAGE(9,4,6) -> 6.3333333
A9: MAN Lion's City 12 G | B9: 280 | C9: 37 | D9: =IF('Duże autobusy'!$D$11="",0, LEN('Duże autobusy'!$D$11) - LEN(SUBSTITUTE('Duże autobusy'!$D$11,",",""))+1) -> 4 | E9: 2 | F9: =AVERAGE(4,4,1) -> 3
A10: SANCITY 12LFH | B10: 344 | C10: 40 | D10: =IF('Duże autobusy'!$D$13="",0, LEN('Duże autobusy'!$D$13) - LEN(SUBSTITUTE('Duże autobusy'!$D$13,",",""))+1) -> 3 | E10: 3.25 | F10: =AVERAGE(10,10,4) -> 8
A11: SANCITY 12LF | B11: 277 | C11: 40 | D11: =IF('Duże autobusy'!$D$14="",0, LEN('Duże autobusy'!$D$14) - LEN(SUBSTITUTE('Duże autobusy'!$D$14,",",""))+1) -> 3 | E11: 1 | F11: =AVERAGE(5,4,3) -> 4
A12: CapaCity L | B12: 360 | C12: 44 | D12: =IF('Duże autobusy'!$D$16="",0, LEN('Duże autobusy'!$D$16) - LEN(SUBSTITUTE('Duże autobusy'!$D$16,",",""))+1) -> 4 | E12: 2 | F12: =AVERAGE(8,9,9) -> 8.6666667
A13: Nesobus 12 | B13: 340 | C13: 37 | D13: =IF('Duże autobusy'!$D$18="",0, LEN('Duże autobusy'!$D$18) - LEN(SUBSTITUTE('Duże autobusy'!$D$18,",",""))+1) -> 3 | E13: 2.9 | F13: =AVERAGE(10,9,10) -> 9.6666667
A15: MAX/MIN | B15: =MAX(B2:B13) -> 408 | C15: =MAX(C2:C13) -> 65 | D15: =MAX(D2:D13) -> 4 | E15: =MIN(E2:E13) -> 1 | F15: =MAX(F2:F13) -> 10
A16: Waga | B16: 0.26 | C16: 0.26 | D16: 0.11 | E16: 0.11 | F16: 0.26 | G16: =SUM(B16:F16) -> 1
A18: Model | B18: moc silnika [KM] | C18: miejsca dla pasażerów | D18: udogodnienia dla niepełnosprawnych | E18: koszt zakupu | F18: prestiż | G18: SAW
A19: Urbino 15 LE electric | B19: =(B2/B$15)*B$16 -> 0.26 | C19: =(C2/C$15)*C$16 -> 0.26 | D19: =(D2/D$15)*D$16 -> 0.055 | E19: =($E$15/E2)*$E$16 -> 0.05 | F19: =(F2/F$15)*F$16 -> 0.182 | G19: =SUM(B19:F19) -> 0.807
A20: Urbino 18 CNG | B20: =(B3/B$15)*B$16 -> 0.20392157 | C20: =(C3/C$15)*C$16 -> 0.22 | D20: =(D3/D$15)*D$16 -> 0.0825 | E20: =($E$15/E3)*$E$16 -> 0.045833333 | F20: =(F3/F$15)*F$16 -> 0.26 | G20: =SUM(B20:F20) -> 0.8122549
A21: Urbino 18 | B21: =(B4/B$15)*B$16 -> 0.19754902 | C21: =(C4/C$15)*C$16 -> 0.216 | D21: =(D4/D$15)*D$16 -> 0.0825 | E21: =($E$15/E4)*$E$16 -> 0.061111111 | F21: =(F4/F$15)*F$16 -> 0.16466667 | G21: =SUM(B21:F21) -> 0.7218268
A22: Urbino 12 | B22: =(B5/B$15)*B$16 -> 0.16313725 | C22: =(C5/C$15)*C$16 -> 0.064 | D22: =(D5/D$15)*D$16 -> 0.0825 | E22: =($E$15/E5)*$E$16 -> 0.11 | F22: =(F5/F$15)*F$16 -> 0.22533333 | G22: =SUM(B22:F22) -> 0.64497059
A23: Urbino 12 CNG | B23: =(B6/B$15)*B$16 -> 0.20392157 | C23: =(C6/C$15)*C$16 -> 0.16 | D23: =(D6/D$15)*D$16 -> 0.0825 | E23: =($E$15/E6)*$E$16 -> 0.1 | F23: =(F6/F$15)*F$16 -> 0.12133333 | G23: =SUM(B23:F23) -> 0.6677549
A24: MAN Lion's City 12 E | B24: =(B7/B$15)*B$16 -> 0.2077451 | C24: =(C7/C$15)*C$16 -> 0.176 | D24: =(D7/D$15)*D$16 -> 0.11 | E24: =($E$15/E7)*$E$16 -> 0.042307692 | F24: =(F7/F$15)*F$16 -> 0.16466667 | G24: =SUM(B24:F24) -> 0.70071946
A25: MAN Lion's Intercity LE 14 | B25: =(B8/B$15)*B$16 -> 0.16887255 | C25: =(C8/C$15)*C$16 -> 0.252 | D25: =(D8/D$15)*D$16 -> 0.0825 | E25: =($E$15/E8)*$E$16 -> 0.061111111 | F25: =(F8/F$15)*F$16 -> 0.16466667 | G25: =SUM(B25:F25) -> 0.72915033
A26: MAN Lion's City 12 G | B26: =(B9/B$15)*B$16 -> 0.17843137 | C26: =(C9/C$15)*C$16 -> 0.148 | D26: =(D9/D$15)*D$16 -> 0.11 | E26: =($E$15/E9)*$E$16 -> 0.055 | F26: =(F9/F$15)*F$16 -> 0.078 | G26: =SUM(B26:F26) -> 0.56943137
A27: SANCITY 12LFH | B27: =(B10/B$15)*B$16 -> 0.21921569 | C27: =(C10/C$15)*C$16 -> 0.16 | D27: =(D10/D$15)*D$16 -> 0.0825 | E27: =($E$15/E10)*$E$16 -> 0.033846154 | F27: =(F10/F$15)*F$16 -> 0.208 | G27: =SUM(B27:F27) -> 0.70356184
A28: SANCITY 12LF | B28: =(B11/B$15)*B$16 -> 0.17651961 | C28: =(C11/C$15)*C$16 -> 0.16 | D28: =(D11/D$15)*D$16 -> 0.0825 | E28: =($E$15/E11)*$E$16 -> 0.11 | F28: =(F11/F$15)*F$16 -> 0.104 | G28: =SUM(B28:F28) -> 0.63301961
A29: CapaCity L | B29: =(B12/B$15)*B$16 -> 0.22941176 | C29: =(C12/C$15)*C$16 -> 0.176 | D29: =(D12/D$15)*D$16 -> 0.11 | E29: =($E$15/E12)*$E$16 -> 0.055 | F29: =(F12/F$15)*F$16 -> 0.22533333 | G29: =SUM(B29:F29) -> 0.7957451
A30: Nesobus 12 | B30: =(B13/B$15)*B$16 -> 0.21666667 | C30: =(C13/C$15)*C$16 -> 0.148 | D30: =(D13/D$15)*D$16 -> 0.0825 | E30: =($E$15/E13)*$E$16 -> 0.037931034 | F30: =(F13/F$15)*F$16 -> 0.25133333 | G30: =SUM(B30:F30) -> 0.73643103
B33: Dane
A34: Model | B34: moc silnika | C34: miejsca pasażerów | D34: udogodnienia niepełnosprawnych | E34: koszty zakupu | F34: prestiż | G34: wartość SAW
A35: CapaCity L | B35: 0.22941176 | C35: 0.176 | D35: 0.11 | E35: 0.055 | F35: 0.22533333 | G35: 0.7957451
A36: MAN Lion's City 12 E | B36: 0.2077451 | C36: 0.176 | D36: 0.11 | E36: 0.042307692 | F36: 0.16466667 | G36: 0.70071946
A37: MAN Lion's City 12 G | B37: 0.17843137 | C37: 0.148 | D37: 0.11 | E37: 0.055 | F37: 0.078 | G37: 0.56943137
A38: MAN Lion's Intercity LE 14 | B38: 0.16887255 | C38: 0.252 | D38: 0.0825 | E38: 0.061111111 | F38: 0.16466667 | G38: 0.72915033
A39: Nesobus 12 | B39: 0.21666667 | C39: 0.148 | D39: 0.0825 | E39: 0.037931034 | F39: 0.25133333 | G39: 0.73643103
A40: SANCITY 12LF | B40: 0.17651961 | C40: 0.16 | D40: 0.0825 | E40: 0.11 | F40: 0.104 | G40: 0.63301961
A41: SANCITY 12LFH | B41: 0.21921569 | C41: 0.16 | D41: 0.0825 | E41: 0.033846154 | F41: 0.208 | G41: 0.70356184
A42: Urbino 12 | B42: 0.16313725 | C42: 0.064 | D42: 0.0825 | E42: 0.11 | F42: 0.22533333 | G42: 0.64497059
A43: Urbino 12 CNG | B43: 0.20392157 | C43: 0.16 | D43: 0.0825 | E43: 0.1 | F43: 0.12133333 | G43: 0.6677549
A44: Urbino 15 LE electric | B44: 0.26 | C44: 0.26 | D44: 0.055 | E44: 0.05 | F44: 0.182 | G44: 0.807
...

Sheet Duże autobusy analiza wrażliwoś
A2: Scenariusz oszczędny
A4: Model | B4: moc silnika [KM] MAX | C4: miejsca dla pasażerów MAX | D4: udogodnienia dla niepełnosprawnych MAX | E4: koszt zakupu [mln zł] MIN | F4: prestiż MAX
A5: Urbino 15 LE electric | B5: 408 | C5: 65 | D5: =IF('Duże autobusy'!$D$3="",0, LEN('Duże autobusy'!$D$3) - LEN(SUBSTITUTE('Duże autobusy'!$D$3,",",""))+1) -> 2 | E5: 2.2 | F5: =AVERAGE(10,6,5) -> 7
A6: Urbino 18 CNG | B6: 320 | C6: 55 | D6: =IF('Duże autobusy'!$D$4="",0, LEN('Duże autobusy'!$D$4) - LEN(SUBSTITUTE('Duże autobusy'!$D$4,",",""))+1) -> 3 | E6: 2.4 | F6: 10
A7: Urbino 18 | B7: 310 | C7: 54 | D7: =IF('Duże autobusy'!$D$5="",0, LEN('Duże autobusy'!$D$5) - LEN(SUBSTITUTE('Duże autobusy'!$D$5,",",""))+1) -> 3 | E7: 1.8 | F7: =AVERAGE(5,4,10) -> 6.3333333
A8: Urbino 12 | B8: 256 | C8: 16 | D8: =IF('Duże autobusy'!$D$6="",0, LEN('Duże autobusy'!$D$6) - LEN(SUBSTITUTE('Duże autobusy'!$D$6,",",""))+1) -> 3 | E8: 1 | F8: =AVERAGE(8,8,10) -> 8.6666667
A9: Urbino 12 CNG | B9: 320 | C9: 40 | D9: =IF('Duże autobusy'!$D$7="",0, LEN('Duże autobusy'!$D$7) - LEN(SUBSTITUTE('Duże autobusy'!$D$7,",",""))+1) -> 3 | E9: 1.1 | F9: =AVERAGE(3,1,10) -> 4.6666667
A10: MAN Lion's City 12 E | B10: 326 | C10: 44 | D10: =IF('Duże autobusy'!$D$9="",0, LEN('Duże autobusy'!$D$9) - LEN(SUBSTITUTE('Duże autobusy'!$D$9,",",""))+1) -> 4 | E10: 2.6 | F10: =AVERAGE(7,4,8) -> 6.3333333
A11: MAN Lion's Intercity LE 14 | B11: 265 | C11: 63 | D11: =IF('Duże autobusy'!$D$10="",0, LEN('Duże autobusy'!$D$10) - LEN(SUBSTITUTE('Duże autobusy'!$D$10,",",""))+1) -> 3 | E11: 1.8 | F11: =AVERAGE(9,4,6) -> 6.3333333
A12: MAN Lion's City 12 G | B12: 280 | C12: 37 | D12: =IF('Duże autobusy'!$D$11="",0, LEN('Duże autobusy'!$D$11) - LEN(SUBSTITUTE('Duże autobusy'!$D$11,",",""))+1) -> 4 | E12: 2 | F12: =AVERAGE(4,4,1) -> 3
A13: SANCITY 12LFH | B13: 344 | C13: 40 | D13: =IF('Duże autobusy'!$D$13="",0, LEN('Duże autobusy'!$D$13) - LEN(SUBSTITUTE('Duże autobusy'!$D$13,",",""))+1) -> 3 | E13: 3.25 | F13: =AVERAGE(10,10,4) -> 8
A14: SANCITY 12LF | B14: 277 | C14: 40 | D14: =IF('Duże autobusy'!$D$14="",0, LEN('Duże autobusy'!$D$14) - LEN(SUBSTITUTE('Duże autobusy'!$D$14,",",""))+1) -> 3 | E14: 1 | F14: =AVERAGE(5,4,3) -> 4
A15: CapaCity L | B15: 360 | C15: 44 | D15: =IF('Duże autobusy'!$D$16="",0, LEN('Duże autobusy'!$D$16) - LEN(SUBSTITUTE('Duże autobusy'!$D$16,",",""))+1) -> 4 | E15: 2 | F15: =AVERAGE(8,9,9) -> 8.6666667
A16: Nesobus 12 | B16: 340 | C16: 37 | D16: =IF('Duże autobusy'!$D$18="",0, LEN('Duże autobusy'!$D$18) - LEN(SUBSTITUTE('Duże autobusy'!$D$18,",",""))+1) -> 3 | E16: 2.9 | F16: =AVERAGE(10,9,10) -> 9.6666667
A18: MAX/MIN | B18: =MAX(B5:B16) -> 408 | C18: =MAX(C5:C16) -> 65 | D18: =MAX(D5:D16) -> 4 | E18: =MIN(E5:E16) -> 1 | F18: =MAX(F5:F16) -> 10
A19: Waga | B19: 0.14 | C19: 0.14 | D19: 0.08 | E19: 0.5 | F19: 0.14 | G19: =SUM(B19:F19) -> 1
A21: Model | B21: moc silnika [KM] | C21: miejsca dla pasażerów | D21: udogodnienia dla niepełnosprawnych | E21: koszt zakupu | F21: prestiż | G21: SAW
A22: Urbino 15 LE electric | B22: =(B5/B$18)*B$19 -> 0.14 | C22: =(C5/C$18)*C$19 -> 0.14 | D22: =(D5/D$18)*D$19 -> 0.04 | E22: =($E$18/E5)*$E$19 -> 0.22727273 | F22: =(F5/F$18)*F$19 -> 0.098 | G22: =SUM(B22:F22) -> 0.64527273
A23: Urbino 18 CNG | B23: =(B6/B$18)*B$19 -> 0.10980392 | C23: =(C6/C$18)*C$19 -> 0.11846154 | D23: =(D6/D$18)*D$19 -> 0.06 | E23: =($E$18/E6)*$E$19 -> 0.20833333 | F23: =(F6/F$18)*F$19 -> 0.14 | G23: =SUM(B23:F23) -> 0.63659879
A24: Urbino 18 | B24: =(B7/B$18)*B$19 -> 0.10637255 | C24: =(C7/C$18)*C$19 -> 0.11630769 | D24: =(D7/D$18)*D$19 -> 0.06 | E24: =($E$18/E7)*$E$19 -> 0.27777778 | F24: =(F7/F$18)*F$19 -> 0.088666667 | G24: =SUM(B24:F24) -> 0.64912469
A25: Urbino 12 | B25: =(B8/B$18)*B$19 -> 0.087843137 | C25: =(C8/C$18)*C$19 -> 0.034461538 | D25: =(D8/D$18)*D$19 -> 0.06 | E25: =($E$18/E8)*$E$19 -> 0.5 | F25: =(F8/F$18)*F$19 -> 0.12133333 | G25: =SUM(B25:F25) -> 0.80363801
A26: Urbino 12 CNG | B26: =(B9/B$18)*B$19 -> 0.10980392 | C26: =(C9/C$18)*C$19 -> 0.086153846 | D26: =(D9/D$18)*D$19 -> 0.06 | E26: =($E$18/E9)*$E$19 -> 0.45454545 | F26: =(F9/F$18)*F$19 -> 0.065333333 | G26: =SUM(B26:F26) -> 0.77583656
A27: MAN Lion's City 12 E | B27: =(B10/B$18)*B$19 -> 0.11186275 | C27: =(C10/C$18)*C$19 -> 0.094769231 | D27: =(D10/D$18)*D$19 -> 0.08 | E27: =($E$18/E10)*$E$19 -> 0.19230769 | F27: =(F10/F$18)*F$19 -> 0.088666667 | G27: =SUM(B27:F27) -> 0.56760633
A28: MAN Lion's Intercity LE 14 | B28: =(B11/B$18)*B$19 -> 0.090931373 | C28: =(C11/C$18)*C$19 -> 0.13569231 | D28: =(D11/D$18)*D$19 -> 0.06 | E28: =($E$18/E11)*$E$19 -> 0.27777778 | F28: =(F11/F$18)*F$19 -> 0.088666667 | G28: =SUM(B28:F28) -> 0.65306812
A29: MAN Lion's City 12 G | B29: =(B12/B$18)*B$19 -> 0.096078431 | C29: =(C12/C$18)*C$19 -> 0.079692308 | D29: =(D12/D$18)*D$19 -> 0.08 | E29: =($E$18/E12)*$E$19 -> 0.25 | F29: =(F12/F$18)*F$19 -> 0.042 | G29: =SUM(B29:F29) -> 0.54777074
A30: SANCITY 12LFH | B30: =(B13/B$18)*B$19 -> 0.11803922 | C30: =(C13/C$18)*C$19 -> 0.086153846 | D30: =(D13/D$18)*D$19 -> 0.06 | E30: =($E$18/E13)*$E$19 -> 0.15384615 | F30: =(F13/F$18)*F$19 -> 0.112 | G30: =SUM(B30:F30) -> 0.53003922
A31: SANCITY 12LF | B31: =(B14/B$18)*B$19 -> 0.09504902 | C31: =(C14/C$18)*C$19 -> 0.086153846 | D31: =(D14/D$18)*D$19 -> 0.06 | E31: =($E$18/E14)*$E$19 -> 0.5 | F31: =(F14/F$18)*F$19 -> 0.056 | G31: =SUM(B31:F31) -> 0.79720287
A32: CapaCity L | B32: =(B15/B$18)*B$19 -> 0.12352941 | C32: =(C15/C$18)*C$19 -> 0.094769231 | D32: =(D15/D$18)*D$19 -> 0.08 | E32: =($E$18/E15)*$E$19 -> 0.25 | F32: =(F15/F$18)*F$19 -> 0.12133333 | G32: =SUM(B32:F32) -> 0.66963198
A33: Nesobus 12 | B33: =(B16/B$18)*B$19 -> 0.11666667 | C33: =(C16/C$18)*C$19 -> 0.079692308 | D33: =(D16/D$18)*D$19 -> 0.06 | E33: =($E$18/E16)*$E$19 -> 0.17241379 | F33: =(F16/F$18)*F$19 -> 0.13533333 | G33: =SUM(B33:F33) -> 0.5641061
A35: Scenariusz techniczny
A37: Model | B37: moc silnika [KM] MAX | C37: miejsca dla pasażerów MAX | D37: udogodnienia dla niepełnosprawnych MAX | E37: koszt zakupu [mln zł] MIN | F37: prestiż MAX
A38: Urbino 15 LE electric | B38: 408 | C38: 65 | D38: =IF('Duże autobusy'!$D$3="",0, LEN('Duże autobusy'!$D$3) - LEN(SUBSTITUTE('Duże autobusy'!$D$3,",",""))+1) -> 2 | E38: 2.2 | F38: =AVERAGE(10,6,5) -> 7
A39: Urbino 18 CNG | B39: 320 | C39: 55 | D39: =IF('Duże autobusy'!$D$4="",0, LEN('Duże autobusy'!$D$4) - LEN(SUBSTITUTE('Duże autobusy'!$D$4,",",""))+1) -> 3 | E39: 2.4 | F39: 10
A40: Urbino 18 | B40: 310 | C40: 54 | D40: =IF('Duże autobusy'!$D$5="",0, LEN('Duże autobusy'!$D$5) - LEN(SUBSTITUTE('Duże autobusy'!$D$5,",",""))+1) -> 3 | E40: 1.8 | F40: =AVERAGE(5,4,10) -> 6.3333333
A41: Urbino 12 | B41: 256 | C41: 16 | D41: =IF('Duże autobusy'!$D$6="",0, LEN('Duże autobusy'!$D$6) - LEN(SUBSTITUTE('Duże autobusy'!$D$6,",",""))+1) -> 3 | E41: 1 | F41: =AVERAGE(8,8,10) -> 8.6666667
A42: Urbino 12 CNG | B42: 320 | C42: 40 | D42: =IF('Duże autobusy'!$D$7="",0, LEN('Duże autobusy'!$D$7) - LEN(SUBSTITUTE('Duże autobusy'!$D$7,",",""))+1) -> 3 | E42: 1.1 | F42: =AVERAGE(3,1,10) -> 4.6666667
A43: MAN Lion's City 12 E | B43: 326 | C43: 44 | D43: =IF('Duże autobusy'!$D$9="",0, LEN('Duże autobusy'!$D$9) - LEN(SUBSTITUTE('Duże autobusy'!$D$9,",",""))+1) -> 4 | E43: 2.6 | F43: =AVERAGE(7,4,8) -> 6.3333333
A44: MAN Lion's Intercity LE 14 | B44: 265 | C44: 63 | D44: =IF('Duże autobusy'!$D$10="",0, LEN('Duże autobusy'!$D$10) - LEN(SUBSTITUTE('Duże autobusy'!$D$10,",",""))+1) -> 3 | E44: 1.8 | F44: =AVERAGE(9,4,6) -> 6.3333333
A45: MAN Lion's City 12 G | B45: 280 | C45: 37 | D45: =IF('Duże autobusy'!$D$11="",0, LEN('Duże autobusy'!$D$11) - LEN(SUBSTITUTE('Duże autobusy'!$D$11,",",""))+1) -> 4 | E45: 2 | F45: =AVERAGE(4,4,1) -> 3
A46: SANCITY 12LFH | B46: 344 | C46: 40 | D46: =IF('Duże autobusy'!$D$13="",0, LEN('Duże autobusy'!$D$13) - LEN(SUBSTITUTE('Duże autobusy'!$D$13,",",""))+1) -> 3 | E46: 3.25 | F46: =AVERAGE(10,10,4) -> 8
...

Sheet Średnie autobusy SAW
A1: Model | B1: moc silnika [KM] MAX | C1: miejsca dla pasażerów MAX | D1: udogodnienia dla niepełnosprawnych MAX | E1: koszt zakupu [mln zł] MIN | F1: prestiż MAX
A2: Urbino 10,5 electric | B2: 340 | C2: 33 | D2: =IF('Średnie autobusy'!D3="",0, LEN('Średnie autobusy'!D3) - LEN(SUBSTITUTE('Średnie autobusy'!D3,",",""))+1) -> 3 | E2: 2.6 | F2: =AVERAGE(6,4,2) -> 4
A3: Urbino 8,9 LE electric | B3: 218 | C3: 27 | D3: =IF('Średnie autobusy'!D4="",0, LEN('Średnie autobusy'!D4) - LEN(SUBSTITUTE('Średnie autobusy'!D4,",",""))+1) -> 4 | E3: 2.4 | F3: =AVERAGE(6,8,10) -> 8
A4: Urbino 8,9 LE | B4: 250 | C4: 33 | D4: =IF('Średnie autobusy'!D5="",0, LEN('Średnie autobusy'!D5) - LEN(SUBSTITUTE('Średnie autobusy'!D5,",",""))+1) -> 4 | E4: 1.1 | F4: =AVERAGE(10,5,5) -> 6.6666667
A5: MAN Lion's City 10 E | B5: 326 | C5: 36 | D5: =IF('Średnie autobusy'!D7="",0, LEN('Średnie autobusy'!D7) - LEN(SUBSTITUTE('Średnie autobusy'!D7,",",""))+1) -> 4 | E5: 2.6 | F5: =AVERAGE(5,5,5) -> 5
A6: SANCITY 9LE | B6: 210 | C6: 16 | D6: =IF('Średnie autobusy'!D9="",0, LEN('Średnie autobusy'!D9) - LEN(SUBSTITUTE('Średnie autobusy'!D9,",",""))+1) -> 4 | E6: 0.6 | F6: =AVERAGE(3,6,4) -> 4.3333333
A7: SANCITY 10LFE | B7: 340 | C7: 24 | D7: =IF('Średnie autobusy'!D10="",0, LEN('Średnie autobusy'!D10) - LEN(SUBSTITUTE('Średnie autobusy'!D10,",",""))+1) -> 4 | E7: 2.2 | F7: =AVERAGE(5,6,4) -> 5
A8: SANCITY 10LF | B8: 247 | C8: 26 | D8: =IF('Średnie autobusy'!D11="",0, LEN('Średnie autobusy'!D11) - LEN(SUBSTITUTE('Średnie autobusy'!D11,",",""))+1) -> 3 | E8: 0.9 | F8: =AVERAGE(5,7,5) -> 5.6666667
A9: Citaro K | B9: 299 | C9: 32 | D9: =IF('Średnie autobusy'!D13="",0, LEN('Średnie autobusy'!D13) - LEN(SUBSTITUTE('Średnie autobusy'!D13,",",""))+1) -> 5 | E9: 1.3 | F9: =AVERAGE(9,9,7) -> 8.3333333
A10: Crossway 10.8LE | B10: 330 | C10: 29 | D10: =IF('Średnie autobusy'!D15="",0, LEN('Średnie autobusy'!D15) - LEN(SUBSTITUTE('Średnie autobusy'!D15,",",""))+1) -> 4 | E10: 1.1 | F10: =AVERAGE(9,7,10) -> 8.6666667
A11: Crossway Pro 10,8 | B11: 360 | C11: 47 | D11: =IF('Średnie autobusy'!D16="",0, LEN('Średnie autobusy'!D16) - LEN(SUBSTITUTE('Średnie autobusy'!D16,",",""))+1) -> 3 | E11: 0.9 | F11: =AVERAGE(8,3,8) -> 6.3333333
A13: MAX/MIN | B13: =MAX(B2:B11) -> 360 | C13: =MAX(C2:C11) -> 47 | D13: =MAX(D2:D11) -> 5 | E13: =MIN(E2:E11) -> 0.6 | F13: =MAX(F2:F11) -> 8.6666667
A14: Waga | B14: 0.26 | C14: 0.26 | D14: 0.11 | E14: 0.11 | F14: 0.26 | G14: =SUM(B14:F14) -> 1
A16: Model | B16: moc silnika [KM] | C16: miejsca dla pasażerów | D16: udogodnienia dla niepełnosprawnych | E16: koszt zakupu | F16: prestiż | G16: SAW
A17: Urbino 10,5 electric | B17: =(B2/B$13)*B$14 -> 0.24555556 | C17: =(C2/C$13)*C$14 -> 0.18255319 | D17: =(D2/D$13)*D$14 -> 0.066 | E17: =($E$13/E2)*$E$14 -> 0.025384615 | F17: =(F2/F$13)*F$14 -> 0.12 | G17: =SUM(B17:F17) -> 0.63949336
A18: Urbino 8,9 LE electric | B18: =(B3/B$13)*B$14 -> 0.15744444 | C18: =(C3/C$13)*C$14 -> 0.1493617 | D18: =(D3/D$13)*D$14 -> 0.088 | E18: =($E$13/E3)*$E$14 -> 0.0275 | F18: =(F3/F$13)*F$14 -> 0.24 | G18: =SUM(B18:F18) -> 0.66230615
A19: Urbino 8,9 LE | B19: =(B4/B$13)*B$14 -> 0.18055556 | C19: =(C4/C$13)*C$14 -> 0.18255319 | D19: =(D4/D$13)*D$14 -> 0.088 | E19: =($E$13/E4)*$E$14 -> 0.06 | F19: =(F4/F$13)*F$14 -> 0.2 | G19: =SUM(B19:F19) -> 0.71110875
A20: MAN Lion's City 10 E | B20: =(B5/B$13)*B$14 -> 0.23544444 | C20: =(C5/C$13)*C$14 -> 0.19914894 | D20: =(D5/D$13)*D$14 -> 0.088 | E20: =($E$13/E5)*$E$14 -> 0.025384615 | F20: =(F5/F$13)*F$14 -> 0.15 | G20: =SUM(B20:F20) -> 0.697978
A21: SANCITY 9LE | B21: =(B6/B$13)*B$14 -> 0.15166667 | C21: =(C6/C$13)*C$14 -> 0.088510638 | D21: =(D6/D$13)*D$14 -> 0.088 | E21: =($E$13/E6)*$E$14 -> 0.11 | F21: =(F6/F$13)*F$14 -> 0.13 | G21: =SUM(B21:F21) -> 0.5681773
A22: SANCITY 10LFE | B22: =(B7/B$13)*B$14 -> 0.24555556 | C22: =(C7/C$13)*C$14 -> 0.13276596 | D22: =(D7/D$13)*D$14 -> 0.088 | E22: =($E$13/E7)*$E$14 -> 0.03 | F22: =(F7/F$13)*F$14 -> 0.15 | G22: =SUM(B22:F22) -> 0.64632151
A23: SANCITY 10LF | B23: =(B8/B$13)*B$14 -> 0.17838889 | C23: =(C8/C$13)*C$14 -> 0.14382979 | D23: =(D8/D$13)*D$14 -> 0.066 | E23: =($E$13/E8)*$E$14 -> 0.073333333 | F23: =(F8/F$13)*F$14 -> 0.17 | G23: =SUM(B23:F23) -> 0.63155201
A24: Citaro K | B24: =(B9/B$13)*B$14 -> 0.21594444 | C24: =(C9/C$13)*C$14 -> 0.17702128 | D24: =(D9/D$13)*D$14 -> 0.11 | E24: =($E$13/E9)*$E$14 -> 0.050769231 | F24: =(F9/F$13)*F$14 -> 0.25 | G24: =SUM(B24:F24) -> 0.80373495
A25: Crossway 10.8LE | B25: =(B10/B$13)*B$14 -> 0.23833333 | C25: =(C10/C$13)*C$14 -> 0.16042553 | D25: =(D10/D$13)*D$14 -> 0.088 | E25: =($E$13/E10)*$E$14 -> 0.06 | F25: =(F10/F$13)*F$14 -> 0.26 | G25: =SUM(B25:F25) -> 0.80675887
A26: Crossway Pro 10,8 | B26: =(B11/B$13)*B$14 -> 0.26 | C26: =(C11/C$13)*C$14 -> 0.26 | D26: =(D11/D$13)*D$14 -> 0.066 | E26: =($E$13/E11)*$E$14 -> 0.073333333 | F26: =(F11/F$13)*F$14 -> 0.19 | G26: =SUM(B26:F26) -> 0.84933333
B29: Dane
A30: Model | B30: moc silnika | C30: miejsca pasażerów | D30: udogodnienia niepełnosprawnych | E30: koszty zakupu | F30: prestiż | G30: wartość SAW
A31: Citaro K | B31: 0.21594444 | C31: 0.17702128 | D31: 0.11 | E31: 0.050769231 | F31: 0.25 | G31: 0.80373495
A32: Crossway 10.8LE | B32: 0.23833333 | C32: 0.16042553 | D32: 0.088 | E32: 0.06 | F32: 0.26 | G32: 0.80675887
A33: Crossway Pro 10,8 | B33: 0.26 | C33: 0.26 | D33: 0.066 | E33: 0.073333333 | F33: 0.19 | G33: 0.84933333
A34: MAN Lion's City 10 E | B34: 0.23544444 | C34: 0.19914894 | D34: 0.088 | E34: 0.025384615 | F34: 0.15 | G34: 0.697978
A35: SANCITY 10LF | B35: 0.17838889 | C35: 0.14382979 | D35: 0.066 | E35: 0.073333333 | F35: 0.17 | G35: 0.63155201
A36: SANCITY 10LFE | B36: 0.24555556 | C36: 0.13276596 | D36: 0.088 | E36: 0.03 | F36: 0.15 | G36: 0.64632151
A37: SANCITY 9LE | B37: 0.15166667 | C37: 0.088510638 | D37: 0.088 | E37: 0.11 | F37: 0.13 | G37: 0.5681773
A38: Urbino 10,5 electric | B38: 0.24555556 | C38: 0.18255319 | D38: 0.066 | E38: 0.025384615 | F38: 0.12 | G38: 0.63949336
A39: Urbino 8,9 LE | B39: 0.18055556 | C39: 0.18255319 | D39: 0.088 | E39: 0.06 | F39: 0.2 | G39: 0.71110875
A40: Urbino 8,9 LE electric | B40: 0.15744444 | C40: 0.1493617 | D40: 0.088 | E40: 0.0275 | F40: 0.24 | G40: 0.66230615
A41: Razem Wynik | B41: 2.1088889 | C41: 1.6761702 | D41: 0.836 | E41: 0.53570513 | F41: 1.86 | G41: 7.0167642

Sheet Średnie autobusy analiza wrazli
A2: Scenariusz oszczędny
A4: Model | B4: moc silnika [KM] MAX | C4: miejsca dla pasażerów MAX | D4: udogodnienia dla niepełnosprawnych MAX | E4: koszt zakupu [mln zł] MIN | F4: prestiż MAX
A5: Urbino 10,5 electric | B5: 340 | C5: 33 | D5: =IF('Średnie autobusy'!$D$3="",0, LEN('Średnie autobusy'!$D$3) - LEN(SUBSTITUTE('Średnie autobusy'!$D$3,",",""))+1) -> 3 | E5: 2.6 | F5: =AVERAGE(6,4,2) -> 4
A6: Urbino 8,9 LE electric | B6: 218 | C6: 27 | D6: =IF('Średnie autobusy'!$D$4="",0, LEN('Średnie autobusy'!$D$4) - LEN(SUBSTITUTE('Średnie autobusy'!$D$4,",",""))+1) -> 4 | E6: 2.4 | F6: =AVERAGE(6,8,10) -> 8
A7: Urbino 8,9 LE | B7: 250 | C7: 33 | D7: =IF('Średnie autobusy'!$D$5="",0, LEN('Średnie autobusy'!$D$5) - LEN(SUBSTITUTE('Średnie autobusy'!$D$5,",",""))+1) -> 4 | E7: 1.1 | F7: =AVERAGE(10,5,5) -> 6.6666667
A8: MAN Lion's City 10 E | B8: 326 | C8: 36 | D8: =IF('Średnie autobusy'!$D$7="",0, LEN('Średnie autobusy'!$D$7) - LEN(SUBSTITUTE('Średnie autobusy'!$D$7,",",""))+1) -> 4 | E8: 2.6 | F8: =AVERAGE(5,5,5) -> 5
A9: SANCITY 9LE | B9: 210 | C9: 16 | D9: =IF('Średnie autobusy'!$D$9="",0, LEN('Średnie autobusy'!$D$9) - LEN(SUBSTITUTE('Średnie autobusy'!$D$9,",",""))+1) -> 4 | E9: 0.6 | F9: =AVERAGE(3,6,4) -> 4.3333333
A10: SANCITY 10LFE | B10: 340 | C10: 24 | D10: =IF('Średnie autobusy'!$D$10="",0, LEN('Średnie autobusy'!$D$10) - LEN(SUBSTITUTE('Średnie autobusy'!$D$10,",",""))+1) -> 4 | E10: 2.2 | F10: =AVERAGE(5,6,4) -> 5
A11: SANCITY 10LF | B11: 247 | C11: 26 | D11: =IF('Średnie autobusy'!$D$11="",0, LEN('Średnie autobusy'!$D$11) - LEN(SUBSTITUTE('Średnie autobusy'!$D$11,",",""))+1) -> 3 | E11: 0.9 | F11: =AVERAGE(5,7,5) -> 5.6666667
A12: Citaro K | B12: 299 | C12: 32 | D12: =IF('Średnie autobusy'!$D$13="",0, LEN('Średnie autobusy'!$D$13) - LEN(SUBSTITUTE('Średnie autobusy'!$D$13,",",""))+1) -> 5 | E12: 1.3 | F12: =AVERAGE(9,9,7) -> 8.3333333
A13: Crossway 10.8LE | B13: 330 | C13: 29 | D13: =IF('Średnie autobusy'!$D$15="",0, LEN('Średnie autobusy'!$D$15) - LEN(SUBSTITUTE('Średnie autobusy'!$D$15,",",""))+1) -> 4 | E13: 1.1 | F13: =AVERAGE(9,7,10) -> 8.6666667
A14: Crossway Pro 10,8 | B14: 360 | C14: 47 | D14: =IF('Średnie autobusy'!$D$16="",0, LEN('Średnie autobusy'!$D$16) - LEN(SUBSTITUTE('Średnie autobusy'!$D$16,",",""))+1) -> 3 | E14: 0.9 | F14: =AVERAGE(8,3,8) -> 6.3333333
A16: MAX/MIN | B16: =MAX(B5:B14) -> 360 | C16: =MAX(C5:C14) -> 47 | D16: =MAX(D5:D14) -> 5 | E16: =MIN(E5:E14) -> 0.6 | F16: =MAX(F5:F14) -> 8.6666667
A17: Waga | B17: 0.14 | C17: 0.14 | D17: 0.08 | E17: 0.5 | F17: 0.14 | G17: =SUM(B17:F17) -> 1
A22: Model | B22: moc silnika [KM] | C22: miejsca dla pasażerów | D22: udogodnienia dla niepełnosprawnych | E22: koszt zakupu | F22: prestiż | G22: SAW
A23: Urbino 10,5 electric | B23: =(B5/B$16)*B$17 -> 0.13222222 | C23: =(C5/C$16)*C$17 -> 0.098297872 | D23: =(D5/D$16)*D$17 -> 0.048 | E23: =($E$16/E5)*$E$17 -> 0.11538462 | F23: =(F5/F$16)*F$17 -> 0.064615385 | G23: =SUM(B23:F23) -> 0.45852009
A24: Urbino 8,9 LE electric | B24: =(B6/B$16)*B$17 -> 0.084777778 | C24: =(C6/C$16)*C$17 -> 0.080425532 | D24: =(D6/D$16)*D$17 -> 0.064 | E24: =($E$16/E6)*$E$17 -> 0.125 | F24: =(F6/F$16)*F$17 -> 0.12923077 | G24: =SUM(B24:F24) -> 0.48343408
A25: Urbino 8,9 LE | B25: =(B7/B$16)*B$17 -> 0.097222222 | C25: =(C7/C$16)*C$17 -> 0.098297872 | D25: =(D7/D$16)*D$17 -> 0.064 | E25: =($E$16/E7)*$E$17 -> 0.27272727 | F25: =(F7/F$16)*F$17 -> 0.10769231 | G25: =SUM(B25:F25) -> 0.63993967
A26: MAN Lion's City 10 E | B26: =(B8/B$16)*B$17 -> 0.12677778 | C26: =(C8/C$16)*C$17 -> 0.10723404 | D26: =(D8/D$16)*D$17 -> 0.064 | E26: =($E$16/E8)*$E$17 -> 0.11538462 | F26: =(F8/F$16)*F$17 -> 0.080769231 | G26: =SUM(B26:F26) -> 0.49416567
A27: SANCITY 9LE | B27: =(B9/B$16)*B$17 -> 0.081666667 | C27: =(C9/C$16)*C$17 -> 0.047659574 | D27: =(D9/D$16)*D$17 -> 0.064 | E27: =($E$16/E9)*$E$17 -> 0.5 | F27: =(F9/F$16)*F$17 -> 0.07 | G27: =SUM(B27:F27) -> 0.76332624
A28: SANCITY 10LFE | B28: =(B10/B$16)*B$17 -> 0.13222222 | C28: =(C10/C$16)*C$17 -> 0.071489362 | D28: =(D10/D$16)*D$17 -> 0.064 | E28: =($E$16/E10)*$E$17 -> 0.13636364 | F28: =(F10/F$16)*F$17 -> 0.080769231 | G28: =SUM(B28:F28) -> 0.48484445
A29: SANCITY 10LF | B29: =(B11/B$16)*B$17 -> 0.096055556 | C29: =(C11/C$16)*C$17 -> 0.077446809 | D29: =(D11/D$16)*D$17 -> 0.048 | E29: =($E$16/E11)*$E$17 -> 0.33333333 | F29: =(F11/F$16)*F$17 -> 0.091538462 | G29: =SUM(B29:F29) -> 0.64637416
A30: Citaro K | B30: =(B12/B$16)*B$17 -> 0.11627778 | C30: =(C12/C$16)*C$17 -> 0.095319149 | D30: =(D12/D$16)*D$17 -> 0.08 | E30: =($E$16/E12)*$E$17 -> 0.23076923 | F30: =(F12/F$16)*F$17 -> 0.13461538 | G30: =SUM(B30:F30) -> 0.65698154
A31: Crossway 10.8LE | B31: =(B13/B$16)*B$17 -> 0.12833333 | C31: =(C13/C$16)*C$17 -> 0.086382979 | D31: =(D13/D$16)*D$17 -> 0.064 | E31: =($E$16/E13)*$E$17 -> 0.27272727 | F31: =(F13/F$16)*F$17 -> 0.14 | G31: =SUM(B31:F31) -> 0.69144358
A32: Crossway Pro 10,8 | B32: =(B14/B$16)*B$17 -> 0.14 | C32: =(C14/C$16)*C$17 -> 0.14 | D32: =(D14/D$16)*D$17 -> 0.048 | E32: =($E$16/E14)*$E$17 -> 0.33333333 | F32: =(F14/F$16)*F$17 -> 0.10230769 | G32: =SUM(B32:F32) -> 0.76364103
A34: Scenariusz techniczny
A36: Model | B36: moc silnika [KM] MAX | C36: miejsca dla pasażerów MAX | D36: udogodnienia dla niepełnosprawnych MAX | E36: koszt zakupu [mln zł] MIN | F36: prestiż MAX
A37: Urbino 10,5 electric | B37: 340 | C37: 33 | D37: =IF('Średnie autobusy'!$D$3="",0, LEN('Średnie autobusy'!$D$3) - LEN(SUBSTITUTE('Średnie autobusy'!$D$3,",",""))+1) -> 3 | E37: 2.6 | F37: =AVERAGE(6,4,2) -> 4
A38: Urbino 8,9 LE electric | B38: 218 | C38: 27 | D38: =IF('Średnie autobusy'!$D$4="",0, LEN('Średnie autobusy'!$D$4) - LEN(SUBSTITUTE('Średnie autobusy'!$D$4,",",""))+1) -> 4 | E38: 2.4 | F38: =AVERAGE(6,8,10) -> 8
A39: Urbino 8,9 LE | B39: 250 | C39: 33 | D39: =IF('Średnie autobusy'!$D$5="",0, LEN('Średnie autobusy'!$D$5) - LEN(SUBSTITUTE('Średnie autobusy'!$D$5,",",""))+1) -> 4 | E39: 1.1 | F39: =AVERAGE(10,5,5) -> 6.6666667
A40: MAN Lion's City 10 E | B40: 326 | C40: 36 | D40: =IF('Średnie autobusy'!$D$7="",0, LEN('Średnie autobusy'!$D$7) - LEN(SUBSTITUTE('Średnie autobusy'!$D$7,",",""))+1) -> 4 | E40: 2.6 | F40: =AVERAGE(5,5,5) -> 5
A41: SANCITY 9LE | B41: 210 | C41: 16 | D41: =IF('Średnie autobusy'!$D$9="",0, LEN('Średnie autobusy'!$D$9) - LEN(SUBSTITUTE('Średnie autobusy'!$D$9,",",""))+1) -> 4 | E41: 0.6 | F41: =AVERAGE(3,6,4) -> 4.3333333
A42: SANCITY 10LFE | B42: 340 | C42: 24 | D42: =IF('Średnie autobusy'!$D$10="",0, LEN('Średnie autobusy'!$D$10) - LEN(SUBSTITUTE('Średnie autobusy'!$D$10,",",""))+1) -> 4 | E42: 2.2 | F42: =AVERAGE(5,6,4) -> 5
A43: SANCITY 10LF | B43: 247 | C43: 26 | D43: =IF('Średnie autobusy'!$D$11="",0, LEN('Średnie autobusy'!$D$11) - LEN(SUBSTITUTE('Średnie autobusy'!$D$11,",",""))+1) -> 3 | E43: 0.9 | F43: =AVERAGE(5,7,5) -> 5.6666667
A44: Citaro K | B44: 299 | C44: 32 | D44: =IF('Średnie autobusy'!$D$13="",0, LEN('Średnie autobusy'!$D$13) - LEN(SUBSTITUTE('Średnie autobusy'!$D$13,",",""))+1) -> 5 | E44: 1.3 | F44: =AVERAGE(9,9,7) -> 8.3333333
A45: Crossway 10.8LE | B45: 330 | C45: 29 | D45: =IF('Średnie autobusy'!$D$15="",0, LEN('Średnie autobusy'!$D$15) - LEN(SUBSTITUTE('Średnie autobusy'!$D$15,",",""))+1) -> 4 | E45: 1.1 | F45: =AVERAGE(9,7,10) -> 8.6666667
A46: Crossway Pro 10,8 | B46: 360 | C46: 47 | D46: =IF('Średnie autobusy'!$D$16="",0, LEN('Średnie autobusy'!$D$16) - LEN(SUBSTITUTE('Średnie autobusy'!$D$16,",",""))+1) -> 3 | E46: 0.9 | F46: =AVERAGE(8,3,8) -> 6.3333333
A48: MAX/MIN | B48: =MAX(B37:B46) -> 360 | C48: =MAX(C37:C46) -> 47 | D48: =MAX(D37:D46) -> 5 | E48: =MIN(E37:E46) -> 0.6 | F48: =MAX(F37:F46) -> 8.6666667
A49: Waga | B49: 0.35 | C49: 0.35 | D49: 0.15 | E49: 0.05 | F49: 0.1 | G49: =SUM(B49:F49) -> 1
A54: Model | B54: moc silnika [KM] | C54: miejsca dla pasażerów | D54: udogodnienia dla niepełnosprawnych | E54: koszt zakupu | F54: prestiż | G54: SAW
...
